Workbook

Sheet Asset-Level Data
A1: Asset ID | B1: Asset Name | C1: Number of Floors | D1: Address | E1: City | F1: State | G1: Zip Code | H1: Latitude | I1: Longitude | J1: Property Type | K1: Floor Area (sq ft) | L1: EN1 - Energy Imported (kWh) | M1: EN1 - Energy Generated On-site (kWh) | N1: EN1 - Energy Exported (kWh) | O1: EUI (kWh/sq ft) | P1: GH1 - Scope 1 (mtCO2e) | Q1: GH1 - Scope 2 Location-based (mtCO2e) | R1: GH1 - Scope 2 Market-based (mtCO2e) | S1: GH1 - Scope 3, unscored (mtCO2e) | T1: WT1 - Water Withdrawals (gal) | U1: WT2 - Discharge to Sensitive Waterways (gal) | V1: WS1 - Waste Diversion Rate (%) | W1: BC1.1 - Design/Construction Certification | X1: BC1.2 - Operational Certification | Y1: BC2 - Ongoing Certification | Z1: Data Coverage (%) | AA1: ENERGY STAR Score (1-100) | AB1: Confidence Tier | AC1: Data Source | AD1: Last Updated | AE1: 12-Month Whole-Building Data Complete | AF1: Assumptions (fabricated demo data)
A2: NY-001 | B2: Hunts Point Logistics Hub | C2: 3 | D2: 1924 Marcus Blvd | E2: Bronx | F2: NY | G2: 10474 | H2: 40.81773 | I2: -73.8868 | J2: Manufacturing | K2: 80000 | L2: 796282 | M2: 102624 | N2: 27052 | O2: =L2/K2 -> 9.953525 | P2: 383.8 | Q2: =L2*$AG$3 -> 143.33076 | R2: 129.5 | S2: 17444.1 | T2: 1980000 | U2: 19186 | V2: 0.539 | W2: LEED BD+C Certified | X2: None | Y2: None | Z2: 0.815 | AA2: 89 | AB2: Estimated | AC2: Landlord submeter | AD2: 2026-06-23 | AE2: Y | AF2: NY grid emission factor used for GH1 Scope 2 (location-based), mtCO2e/kWh - illustrative, not sourced
A3: NY-002 | B3: Navy Yard Industrial Park - Bldg 1 | C3: 1 | D3: 5674 Commerce Dr | E3: Brooklyn | F3: NY | G3: 11205 | H3: 40.69191 | I3: -73.96266 | J3: Cold Storage | K3: 339000 | L3: 4309477 | M3: 222394 | N3: 78782 | O3: =L3/K3 -> 12.712322 | P3: 48.4 | Q3: =L3*$AG$3 -> 775.70586 | R3: 732.4 | S3: 274875.3 | T3: 1950469 | U3: 0 | V3: 0.422 | W3: None | X3: LEED O+M Silver | Y3: None | Z3: 0.637 | AA3: 42 | AB3: Verified | AC3: Landlord submeter | AD3: 2026-07-19 | AE3: Y | AF3: Grid factor value | AG3: 0.00018
A4: NY-003 | B4: LIC Fulfillment Center | C4: 1 | D4: 1407 Corporate Pkwy | E4: Queens | F4: NY | G4: 11101 | H4: 40.75203 | I4: -73.9509 | J4: Flex Industrial | K4: 293000 | L4: 4203889 | M4: 0 | N4: 0 | O4: =L4/K4 -> 14.347744 | P4: 230.9 | Q4: =L4*$AG$3 -> 756.70002 | R4: 735.4 | S4: 253118.3 | T4: 2025433 | U4: 0 | V4: 0.226 | W4: None | X4: None | Y4: None | Z4: 0.758 | AA4: 55 | AB4: Missing | AC4: Landlord submeter | AD4: 2026-06-20 | AE4: N | AF4: All asset data below is synthetic/fabricated for prototyping and does not represent real buildings.
A5: NY-004 | B5: Harbor View Cross-Dock Terminal | C5: 1 | D5: 1016 Industrial Loop | E5: Staten Island | F5: NY | G5: 10314 | H5: 40.60714 | I5: -74.112 | J5: Light Industrial | K5: 289000 | L5: 3935112 | M5: 588599 | N5: 159012 | O5: =L5/K5 -> 13.616304 | P5: 12.8 | Q5: =L5*$AG$3 -> 708.32016 | R5: 703.5 | S5: 196574.1 | T5: 3089988 | U5: 0 | V5: 0.271 | W5: None | X5: None | Y5: ENERGY STAR Certified 2025 | Z5: 0.803 | AA5: 54 | AB5: Estimated | AC5: Estimate - prior year carried forward | AD5: 2026-05-22 | AE5: Y
A6: NY-005 | B6: Cross-County Cold Storage Facility | C6: 1 | D6: 6030 Distribution Way | E6: Yonkers | F6: NY | G6: 10701 | H6: 40.94115 | I6: -73.90593 | J6: Logistics/Cross-dock | K6: 279000 | L6: 4159672 | M6: 0 | N6: 0 | O6: =L6/K6 -> 14.909219 | P6: 9.2 | Q6: =L6*$AG$3 -> 748.74096 | R6: 626.7 | S6: 123121.8 | T6: 2757078 | U6: 0 | V6: 0.426 | W6: LEED BD+C Silver | X6: LEED O+M Certified | Y6: None | Z6: 0.937 | AA6: 38 | AB6: Estimated | AC6: Utility API feed | AD6: 2026-06-27 | AE6: N
A7: NY-006 | B7: Sound Shore Manufacturing Plant | C7: 1 | D7: 4471 Enterprise Ave | E7: New Rochelle | F7: NY | G7: 10801 | H7: 40.9083 | I7: -73.78643 | J7: Warehouse/Distribution | K7: 711000 | L7: 7262302 | M7: 919778 | N7: 290561 | O7: =L7/K7 -> 10.214208 | P7: 45.7 | Q7: =L7*$AG$3 -> 1307.2144 | R7: 1264.6 | S7: 366462.3 | T7: 1951606 | U7: 0 | V7: 0.719 | W7: None | X7: None | Y7: None | Z7: 0.893 | AA7: 72 | AB7: Missing | AC7: Utility API feed | AD7: 2026-05-20 | AE7: Y
A8: NY-007 | B8: Saw Mill Flex Industrial Campus | C8: 2 | D8: 8105 Fulton Industrial Rd | E8: Mount Vernon | F8: NY | G8: 10550 | H8: 40.90484 | I8: -73.83984 | J8: Manufacturing | K8: 74000 | L8: 1612792 | M8: 0 | N8: 0 | O8: =L8/K8 -> 21.794486 | P8: 155.6 | Q8: =L8*$AG$3 -> 290.30256 | R8: 248.8 | S8: 55564.4 | T8: 1978020 | U8: 48513 | V8: 0.702 | W8: None | X8: None | Y8: ENERGY STAR Certified 2025 | Z8: 0.764 | AA8: 73 | AB8: Verified | AC8: Estimate - prior year carried forward | AD8: 2026-02-27 | AE8: Y
A9: NY-008 | B9: Broadway Corridor Warehouse | C9: 1 | D9: 3395 Harbor Logistics Ln | E9: Elmsford | F9: NY | G9: 10523 | H9: 41.06308 | I9: -73.82307 | J9: Cold Storage | K9: 374000 | L9: 4947229 | M9: 0 | N9: 0 | O9: =L9/K9 -> 13.227885 | P9: 14.9 | Q9: =L9*$AG$3 -> 890.50122 | R9: 785.5 | S9: 117949.6 | T9: 803067 | U9: 0 | V9: 0.557 | W9: None | X9: None | Y9: ENERGY STAR Certified 2025 | Z9: 0.834 | AA9: 52 | AB9: Verified | AC9: Utility API feed | AD9: 2026-07-20 | AE9: Y
A10: NY-009 | B10: Sunrise Supply Chain Center | C10: 2 | D10: 1260 Trade Center Dr | E10: Hicksville | F10: NY | G10: 11801 | H10: 40.76316 | I10: -73.52172 | J10: Flex Industrial | K10: 581000 | L10: 6390602 | M10: 973043 | N10: 263999 | O10: =L10/K10 -> 10.999315 | P10: 47.1 | Q10: =L10*$AG$3 -> 1150.3084 | R10: 781.5 | S10: 437435.6 | T10: 1936397 | U10: 125202 | V10: 0.451 | W10: LEED BD+C Silver | X10: None | Y10: ENERGY STAR Certified 2025 | Z10: 0.844 | AA10: 79 | AB10: Verified | AC10: Estimate - prior year carried forward | AD10: 2026-06-20 | AE10: Y
A11: NY-010 | B11: Great South Bay Distribution Center | C11: 1 | D11: 1890 Gateway Blvd | E11: Bay Shore | F11: NY | G11: 11706 | H11: 40.71673 | I11: -73.24467 | J11: Light Industrial | K11: 309000 | L11: 3078428 | M11: 294037 | N11: 106543 | O11: =L11/K11 -> 9.9625502 | P11: 525.2 | Q11: =L11*$AG$3 -> 554.11704 | R11: 443.3 | S11: 219670.5 | T11: 829776 | U11: 0 | V11: 0.526 | W11: None | X11: None | Y11: None | Z11: 0.625 | AA11: 69 | AB11: Verified | AC11: Estimate - prior year carried forward | AD11: 2026-01-15 | AE11: Y
A12: NY-011 | B12: Long Island Logistics Hub | C12: 1 | D12: 6309 Freight St | E12: Ronkonkoma | F12: NY | G12: 11779 | H12: 40.83681 | I12: -73.1306 | J12: Logistics/Cross-dock | K12: 57000 | L12: 1081688 | M12: 0 | N12: 0 | O12: =L12/K12 -> 18.976982 | P12: 57.4 | Q12: =L12*$AG$3 -> 194.70384 | R12: 185.6 | S12: 86238 | T12: 335751 | U12: 0 | V12: 0.279 | W12: None | X12: None | Y12: None | Z12: 0.811 | AA12: 72 | AB12: Verified | AC12: Tenant self-report | AD12: 2026-01-11 | AE12: Y
A13: NY-012 | B13: Bethpage Industrial Park - Bldg 1 | C13: 1 | D13: 9671 Depot Ave | E13: Farmingdale | F13: NY | G13: 11735 | H13: 40.73266 | I13: -73.43915 | J13: Warehouse/Distribution | K13: 543000 | L13: 5540803 | M13: 0 | N13: 0 | O13: =L13/K13 -> 10.204057 | P13: 120.8 | Q13: =L13*$AG$3 -> 997.34454 | R13: 711.7 | S13: 308634.4 | T13: 4378752 | U13: 65682 | V13: 0.75 | W13: None | X13: None | Y13: None | Z13: 0.587 | AA13: 80 | AB13: Verified | AC13: Tenant self-report | AD13: 2026-03-16 | AE13: Y
A14: NY-013 | B14: Half Hollow Fulfillment Center | C14: 2 | D14: 5247 Terminal Rd | E14: Melville | F14: NY | G14: 11747 | H14: 40.78901 | I14: -73.42358 | J14: Manufacturing | K14: 299000 | L14: 5094066 | M14: 0 | N14: 0 | O14: =L14/K14 -> 17.03701 | P14: 603.9 | Q14: =L14*$AG$3 -> 916.93188 | R14: 679.5 | S14: 387882.9 | T14: 617497 | U14: 0 | V14: 0.54 | W14: None | X14: None | Y14: None | Z14: 0.646 | AA14: 54 | AB14: Verified | AC14: Tenant self-report | AD14: 2026-01-17 | AE14: N
A15: NY-014 | B15: Hudson Valley Cross-Dock Terminal | C15: 1 | D15: 6154 Cross Dock Ct | E15: Hauppauge | F15: NY | G15: 11788 | H15: 40.81185 | I15: -73.19533 | J15: Cold Storage | K15: 346000 | L15: 6175947 | M15: 0 | N15: 0 | O15: =L15/K15 -> 17.849558 | P15: 39.2 | Q15: =L15*$AG$3 -> 1111.6705 | R15: 850 | S15: 126417.8 | T15: 5231520 | U15: 265789 | V15: 0.781 | W15: None | X15: LEED O+M Certified | Y15: None | Z15: 0.95 | AA15: 85 | AB15: Verified | AC15: Tenant self-report | AD15: 2026-03-16 | AE15: Y
A16: NY-015 | B16: Mid-Hudson Cold Storage Facility | C16: 1 | D16: 5717 Warehouse Row | E16: Newburgh | F16: NY | G16: 12550 | H16: 41.50715 | I16: -74.00334 | J16: Flex Industrial | K16: 263000 | L16: 3964916 | M16: 0 | N16: 0 | O16: =L16/K16 -> 15.075726 | P16: 3 | Q16: =L16*$AG$3 -> 713.68488 | R16: 577.5 | S16: 230191.4 | T16: 3692520 | U16: 102710 | V16: 0.264 | W16: None | X16: None | Y16: ENERGY STAR Certified 2025 | Z16: 0.749 | AA16: 83 | AB16: Verified | AC16: Utility API feed | AD16: 2026-01-12 | AE16: Y
... A31: NY-030 | B31: State Street Capital Mixed-Use Tower | C31: 25 | D31: 60 State St | E31: Downtown Albany | F31: NY | G31: 12207 | H31: 42.65403 | I31: -73.75385 | J31: Mixed-Use Residential/Commercial | K31: 252000 | L31: 4878144 | M31: 0 | N31: 0 | O31: =L31/K31 -> 19.357714 | P31: 155.8 | Q31: =L31*$AG$3 -> 878.06592 | R31: 858.8 | S31: 377702.1 | T31: 2791101 | U31: 0 | V31: 0.277 | W31: LEED BD+C Gold | X31: LEED O+M Gold | Y31: None | Z31: 0.658 | AA31: 52 | AB31: Verified | AC31: Tenant self-report | AD31: 2026-01-18 | AE31: Y
B33: PORTFOLIO TOTAL / WEIGHTED AVG | C33: =SUMPRODUCT(C2:C31,$K2:$K31)/SUM($K2:$K31) -> 3.6734038 | K33: =SUM(K2:K31) -> 11825000 | L33: =SUM(L2:L31) -> 175179634 | M33: =SUM(M2:M31) -> 3225324 | N33: =SUM(N2:N31) -> 951585 | O33: =SUMPRODUCT(O2:O31,$K2:$K31)/SUM($K2:$K31) -> 14.814345 | P33: =SUM(P2:P31) -> 5565.5 | Q33: =SUM(Q2:Q31) -> 31532.334 | R33: =SUM(R2:R31) -> 26716.4 | S33: =SUM(S2:S31) -> 10334416 | T33: =SUM(T2:T31) -> 66364001 | U33: =SUM(U2:U31) -> 1403061 | V33: =SUMPRODUCT(V2:V31,$K2:$K31)/SUM($K2:$K31) -> 0.50634114 | Z33: =SUMPRODUCT(Z2:Z31,$K2:$K31)/SUM($K2:$K31) -> 0.74676727 | AA33: =SUMPRODUCT(AA2:AA31,$K2:$K31)/SUM($K2:$K31) -> 69.083044 | AE33: =COUNTIF(AE2:AE31,"Y")&" of "&COUNTA(AE2:AE31)&" complete" -> 22 of 30 complete

Sheet Baseline & Targets
A1: Asset ID | B1: Asset Name | C1: Metric | D1: Unit | E1: Direction | F1: Baseline Value | G1: Baseline Year | H1: Current Value | I1: Target Value | J1: Target Year | K1: % Progress to Target | L1: Variance vs Target | M1: Status | P1: Assumptions (fabricated demo data)
A2: NY-001 | B2: Hunts Point Logistics Hub | C2: GHG Emissions (Scope 1+2, location-based) | D2: mtCO2e | E2: Lower is better | F2: 657.4 | G2: 2019 | H2: ='Asset-Level Data'!P2+'Asset-Level Data'!Q2 -> 527.13076 | I2: =F2*(1-$Q$3) -> 394.44 | J2: 2030 | K2: =(F2-H2)/(F2-I2) -> 0.49539565 | L2: =H2-I2 -> 132.69076 | M2: =IF(K2>=1,"Target Met",IF(K2>=0.75,"On Track",IF(K2>=0.4,"At Risk","Off Track"))) -> At Risk | P2: Reduction targets (lower-is-better metrics, baseline -> target year)
A3: NY-002 | B3: Navy Yard Industrial Park - Bldg 1 | C3: GHG Emissions (Scope 1+2, location-based) | D3: mtCO2e | E3: Lower is better | F3: 985 | G3: 2019 | H3: ='Asset-Level Data'!P3+'Asset-Level Data'!Q3 -> 824.10586 | I3: =F3*(1-$Q$3) -> 591 | J3: 2030 | K3: =(F3-H3)/(F3-I3) -> 0.40836076 | L3: =H3-I3 -> 233.10586 | M3: =IF(K3>=1,"Target Met",IF(K3>=0.75,"On Track",IF(K3>=0.4,"At Risk","Off Track"))) -> At Risk | P3: GHG reduction target | Q3: 0.4
A4: NY-003 | B4: LIC Fulfillment Center | C4: GHG Emissions (Scope 1+2, location-based) | D4: mtCO2e | E4: Lower is better | F4: 1328.6 | G4: 2019 | H4: ='Asset-Level Data'!P4+'Asset-Level Data'!Q4 -> 987.60002 | I4: =F4*(1-$Q$3) -> 797.16 | J4: 2030 | K4: =(F4-H4)/(F4-I4) -> 0.64165283 | L4: =H4-I4 -> 190.44002 | M4: =IF(K4>=1,"Target Met",IF(K4>=0.75,"On Track",IF(K4>=0.4,"At Risk","Off Track"))) -> At Risk | P4: EUI reduction target | Q4: 0.2
A5: NY-004 | B5: Harbor View Cross-Dock Terminal | C5: GHG Emissions (Scope 1+2, location-based) | D5: mtCO2e | E5: Lower is better | F5: 845 | G5: 2019 | H5: ='Asset-Level Data'!P5+'Asset-Level Data'!Q5 -> 721.12016 | I5: =F5*(1-$Q$3) -> 507 | J5: 2030 | K5: =(F5-H5)/(F5-I5) -> 0.3665084 | L5: =H5-I5 -> 214.12016 | M5: =IF(K5>=1,"Target Met",IF(K5>=0.75,"On Track",IF(K5>=0.4,"At Risk","Off Track"))) -> Off Track | P5: Water reduction target | Q5: 0.15
A6: NY-005 | B6: Cross-County Cold Storage Facility | C6: GHG Emissions (Scope 1+2, location-based) | D6: mtCO2e | E6: Lower is better | F6: 993.5 | G6: 2019 | H6: ='Asset-Level Data'!P6+'Asset-Level Data'!Q6 -> 757.94096 | I6: =F6*(1-$Q$3) -> 596.1 | J6: 2030 | K6: =(F6-H6)/(F6-I6) -> 0.59275048 | L6: =H6-I6 -> 161.84096 | M6: =IF(K6>=1,"Target Met",IF(K6>=0.75,"On Track",IF(K6>=0.4,"At Risk","Off Track"))) -> At Risk | P6: Fixed targets (higher-is-better metrics)
A7: NY-006 | B7: Sound Shore Manufacturing Plant | C7: GHG Emissions (Scope 1+2, location-based) | D7: mtCO2e | E7: Lower is better | F7: 1704.3 | G7: 2019 | H7: ='Asset-Level Data'!P7+'Asset-Level Data'!Q7 -> 1352.9144 | I7: =F7*(1-$Q$3) -> 1022.58 | J7: 2030 | K7: =(F7-H7)/(F7-I7) -> 0.51543983 | L7: =H7-I7 -> 330.33436 | M7: =IF(K7>=1,"Target Met",IF(K7>=0.75,"On Track",IF(K7>=0.4,"At Risk","Off Track"))) -> At Risk | P7: Waste diversion fixed target | Q7: 0.75
A8: NY-007 | B8: Saw Mill Flex Industrial Campus | C8: GHG Emissions (Scope 1+2, location-based) | D8: mtCO2e | E8: Lower is better | F8: 520.5 | G8: 2019 | H8: ='Asset-Level Data'!P8+'Asset-Level Data'!Q8 -> 445.90256 | I8: =F8*(1-$Q$3) -> 312.3 | J8: 2030 | K8: =(F8-H8)/(F8-I8) -> 0.35829702 | L8: =H8-I8 -> 133.60256 | M8: =IF(K8>=1,"Target Met",IF(K8>=0.75,"On Track",IF(K8>=0.4,"At Risk","Off Track"))) -> Off Track | P8: ENERGY STAR fixed target | Q8: 75
A9: NY-008 | B9: Broadway Corridor Warehouse | C9: GHG Emissions (Scope 1+2, location-based) | D9: mtCO2e | E9: Lower is better | F9: 1179 | G9: 2019 | H9: ='Asset-Level Data'!P9+'Asset-Level Data'!Q9 -> 905.40122 | I9: =F9*(1-$Q$3) -> 707.4 | J9: 2030 | K9: =(F9-H9)/(F9-I9) -> 0.58015008 | L9: =H9-I9 -> 198.00122 | M9: =IF(K9>=1,"Target Met",IF(K9>=0.75,"On Track",IF(K9>=0.4,"At Risk","Off Track"))) -> At Risk | P9: Data coverage fixed target | Q9: 0.75
A10: NY-009 | B10: Sunrise Supply Chain Center | C10: GHG Emissions (Scope 1+2, location-based) | D10: mtCO2e | E10: Lower is better | F10: 1390.5 | G10: 2019 | H10: ='Asset-Level Data'!P10+'Asset-Level Data'!Q10 -> 1197.4084 | I10: =F10*(1-$Q$3) -> 834.3 | J10: 2030 | K10: =(F10-H10)/(F10-I10) -> 0.34716224 | L10: =H10-I10 -> 363.10836 | M10: =IF(K10>=1,"Target Met",IF(K10>=0.75,"On Track",IF(K10>=0.4,"At Risk","Off Track"))) -> Off Track | P10: Baseline values are fabricated for prototyping and do not represent real historical performance.
A11: NY-010 | B11: Great South Bay Distribution Center | C11: GHG Emissions (Scope 1+2, location-based) | D11: mtCO2e | E11: Lower is better | F11: 1381.6 | G11: 2019 | H11: ='Asset-Level Data'!P11+'Asset-Level Data'!Q11 -> 1079.317 | I11: =F11*(1-$Q$3) -> 828.96 | J11: 2030 | K11: =(F11-H11)/(F11-I11) -> 0.54697988 | L11: =H11-I11 -> 250.35704 | M11: =IF(K11>=1,"Target Met",IF(K11>=0.75,"On Track",IF(K11>=0.4,"At Risk","Off Track"))) -> At Risk
A12: NY-011 | B12: Long Island Logistics Hub | C12: GHG Emissions (Scope 1+2, location-based) | D12: mtCO2e | E12: Lower is better | F12: 295.2 | G12: 2019 | H12: ='Asset-Level Data'!P12+'Asset-Level Data'!Q12 -> 252.10384 | I12: =F12*(1-$Q$3) -> 177.12 | J12: 2030 | K12: =(F12-H12)/(F12-I12) -> 0.36497425 | L12: =H12-I12 -> 74.98384 | M12: =IF(K12>=1,"Target Met",IF(K12>=0.75,"On Track",IF(K12>=0.4,"At Risk","Off Track"))) -> Off Track
A13: NY-012 | B13: Bethpage Industrial Park - Bldg 1 | C13: GHG Emissions (Scope 1+2, location-based) | D13: mtCO2e | E13: Lower is better | F13: 1316.3 | G13: 2019 | H13: ='Asset-Level Data'!P13+'Asset-Level Data'!Q13 -> 1118.1445 | I13: =F13*(1-$Q$3) -> 789.78 | J13: 2030 | K13: =(F13-H13)/(F13-I13) -> 0.37634935 | L13: =H13-I13 -> 328.36454 | M13: =IF(K13>=1,"Target Met",IF(K13>=0.75,"On Track",IF(K13>=0.4,"At Risk","Off Track"))) -> Off Track
A14: NY-013 | B14: Half Hollow Fulfillment Center | C14: GHG Emissions (Scope 1+2, location-based) | D14: mtCO2e | E14: Lower is better | F14: 1942.6 | G14: 2019 | H14: ='Asset-Level Data'!P14+'Asset-Level Data'!Q14 -> 1520.8319 | I14: =F14*(1-$Q$3) -> 1165.56 | J14: 2030 | K14: =(F14-H14)/(F14-I14) -> 0.54278817 | L14: =H14-I14 -> 355.27188 | M14: =IF(K14>=1,"Target Met",IF(K14>=0.75,"On Track",IF(K14>=0.4,"At Risk","Off Track"))) -> At Risk
A15: NY-014 | B15: Hudson Valley Cross-Dock Terminal | C15: GHG Emissions (Scope 1+2, location-based) | D15: mtCO2e | E15: Lower is better | F15: 1609 | G15: 2019 | H15: ='Asset-Level Data'!P15+'Asset-Level Data'!Q15 -> 1150.8705 | I15: =F15*(1-$Q$3) -> 965.4 | J15: 2030 | K15: =(F15-H15)/(F15-I15) -> 0.7118234 | L15: =H15-I15 -> 185.47046 | M15: =IF(K15>=1,"Target Met",IF(K15>=0.75,"On Track",IF(K15>=0.4,"At Risk","Off Track"))) -> At Risk
A16: NY-015 | B16: Mid-Hudson Cold Storage Facility | C16: GHG Emissions (Scope 1+2, location-based) | D16: mtCO2e | E16: Lower is better | F16: 850.8 | G16: 2019 | H16: ='Asset-Level Data'!P16+'Asset-Level Data'!Q16 -> 716.68488 | I16: =F16*(1-$Q$3) -> 510.48 | J16: 2030 | K16: =(F16-H16)/(F16-I16) -> 0.39408533 | L16: =H16-I16 -> 206.20488 | M16: =IF(K16>=1,"Target Met",IF(K16>=0.75,"On Track",IF(K16>=0.4,"At Risk","Off Track"))) -> Off Track
A17: NY-016 | B17: Rondout Manufacturing Plant | C17: GHG Emissions (Scope 1+2, location-based) | D17: mtCO2e | E17: Lower is better | F17: 2401.4 | G17: 2019 | H17: ='Asset-Level Data'!P17+'Asset-Level Data'!Q17 -> 1973.2386 | I17: =F17*(1-$Q$3) -> 1440.84 | J17: 2030 | K17: =(F17-H17)/(F17-I17) -> 0.44574144 | L17: =H17-I17 -> 532.3986 | M17: =IF(K17>=1,"Target Met",IF(K17>=0.75,"On Track",IF(K17>=0.4,"At Risk","Off Track"))) -> At Risk
A18: NY-017 | B18: Capital Region Flex Industrial Campus | C18: GHG Emissions (Scope 1+2, location-based) | D18: mtCO2e | E18: Lower is better | F18: 1522.9 | G18: 2019 | H18: ='Asset-Level Data'!P18+'Asset-Level Data'!Q18 -> 1137.9801 | I18: =F18*(1-$Q$3) -> 913.74 | J18: 2030 | K18: =(F18-H18)/(F18-I18) -> 0.63188634 | L18: =H18-I18 -> 224.24012 | M18: =IF(K18>=1,"Target Met",IF(K18>=0.75,"On Track",IF(K18>=0.4,"At Risk","Off Track"))) -> At Risk
A19: NY-018 | B19: Mohawk Valley Warehouse | C19: GHG Emissions (Scope 1+2, location-based) | D19: mtCO2e | E19: Lower is better | F19: 301.2 | G19: 2019 | H19: ='Asset-Level Data'!P19+'Asset-Level Data'!Q19 -> 210.02412 | I19: =F19*(1-$Q$3) -> 180.72 | J19: 2030 | K19: =(F19-H19)/(F19-I19) -> 0.75677191 | L19: =H19-I19 -> 29.30412 | M19: =IF(K19>=1,"Target Met",IF(K19>=0.75,"On Track",IF(K19>=0.4,"At Risk","Off Track"))) -> On Track
A20: NY-019 | B20: Hudson-Mohawk Supply Chain Center | C20: GHG Emissions (Scope 1+2, location-based) | D20: mtCO2e | E20: Lower is better | F20: 1369 | G20: 2019 | H20: ='Asset-Level Data'!P20+'Asset-Level Data'!Q20 -> 1034.6823 | I20: =F20*(1-$Q$3) -> 821.4 | J20: 2030 | K20: =(F20-H20)/(F20-I20) -> 0.61051435 | L20: =H20-I20 -> 213.28234 | M20: =IF(K20>=1,"Target Met",IF(K20>=0.75,"On Track",IF(K20>=0.4,"At Risk","Off Track"))) -> At Risk
A21: NY-020 | B21: Central New York Distribution Center | C21: GHG Emissions (Scope 1+2, location-based) | D21: mtCO2e | E21: Lower is better | F21: 2134.4 | G21: 2019 | H21: ='Asset-Level Data'!P21+'Asset-Level Data'!Q21 -> 1681.924 | I21: =F21*(1-$Q$3) -> 1280.64 | J21: 2030 | K21: =(F21-H21)/(F21-I21) -> 0.5299803 | L21: =H21-I21 -> 401.28402 | M21: =IF(K21>=1,"Target Met",IF(K21>=0.75,"On Track",IF(K21>=0.4,"At Risk","Off Track"))) -> At Risk
A22: NY-021 | B22: Genesee Valley Logistics Hub | C22: GHG Emissions (Scope 1+2, location-based) | D22: mtCO2e | E22: Lower is better | F22: 2154 | G22: 2019 | H22: ='Asset-Level Data'!P22+'Asset-Level Data'!Q22 -> 1492.8521 | I22: =F22*(1-$Q$3) -> 1292.4 | J22: 2030 | K22: =(F22-H22)/(F22-I22) -> 0.76734905 | L22: =H22-I22 -> 200.45206 | M22: =IF(K22>=1,"Target Met",IF(K22>=0.75,"On Track",IF(K22>=0.4,"At Risk","Off Track"))) -> On Track
... A31: NY-030 | B31: State Street Capital Mixed-Use Tower | C31: GHG Emissions (Scope 1+2, location-based) | D31: mtCO2e | E31: Lower is better | F31: 1398.8 | G31: 2019 | H31: ='Asset-Level Data'!P31+'Asset-Level Data'!Q31 -> 1033.8659 | I31: =F31*(1-$Q$3) -> 839.28 | J31: 2030 | K31: =(F31-H31)/(F31-I31) -> 0.65222705 | L31: =H31-I31 -> 194.58592 | M31: =IF(K31>=1,"Target Met",IF(K31>=0.75,"On Track",IF(K31>=0.4,"At Risk","Off Track"))) -> At Risk
A32: NY-001 | B32: Hunts Point Logistics Hub | C32: Energy Use Intensity (EUI) | D32: kWh/sq ft | E32: Lower is better | F32: 11.8 | G32: 2019 | H32: ='Asset-Level Data'!O2 -> 9.953525 | I32: =F32*(1-$Q$4) -> 9.44 | J32: 2030 | K32: =(F32-H32)/(F32-I32) -> 0.78240466 | L32: =H32-I32 -> 0.513525 | M32: =IF(K32>=1,"Target Met",IF(K32>=0.75,"On Track",IF(K32>=0.4,"At Risk","Off Track"))) -> On Track
A33: NY-002 | B33: Navy Yard Industrial Park - Bldg 1 | C33: Energy Use Intensity (EUI) | D33: kWh/sq ft | E33: Lower is better | F33: 15.8 | G33: 2019 | H33: ='Asset-Level Data'!O3 -> 12.712322 | I33: =F33*(1-$Q$4) -> 12.64 | J33: 2030 | K33: =(F33-H33)/(F33-I33) -> 0.97711344 | L33: =H33-I33 -> 0.072321534 | M33: =IF(K33>=1,"Target Met",IF(K33>=0.75,"On Track",IF(K33>=0.4,"At Risk","Off Track"))) -> On Track
A34: NY-003 | B34: LIC Fulfillment Center | C34: Energy Use Intensity (EUI) | D34: kWh/sq ft | E34: Lower is better | F34: 20 | G34: 2019 | H34: ='Asset-Level Data'!O4 -> 14.347744 | I34: =F34*(1-$Q$4) -> 16 | J34: 2030 | K34: =(F34-H34)/(F34-I34) -> 1.413064 | L34: =H34-I34 -> -1.652256 | M34: =IF(K34>=1,"Target Met",IF(K34>=0.75,"On Track",IF(K34>=0.4,"At Risk","Off Track"))) -> Target Met
A35: NY-004 | B35: Harbor View Cross-Dock Terminal | C35: Energy Use Intensity (EUI) | D35: kWh/sq ft | E35: Lower is better | F35: 16.4 | G35: 2019 | H35: ='Asset-Level Data'!O5 -> 13.616304 | I35: =F35*(1-$Q$4) -> 13.12 | J35: 2030 | K35: =(F35-H35)/(F35-I35) -> 0.84868765 | L35: =H35-I35 -> 0.4963045 | M35: =IF(K35>=1,"Target Met",IF(K35>=0.75,"On Track",IF(K35>=0.4,"At Risk","Off Track"))) -> On Track
A36: NY-005 | B36: Cross-County Cold Storage Facility | C36: Energy Use Intensity (EUI) | D36: kWh/sq ft | E36: Lower is better | F36: 19.7 | G36: 2019 | H36: ='Asset-Level Data'!O6 -> 14.909219 | I36: =F36*(1-$Q$4) -> 15.76 | J36: 2030 | K36: =(F36-H36)/(F36-I36) -> 1.2159344 | L36: =H36-I36 -> -0.85078136 | M36: =IF(K36>=1,"Target Met",IF(K36>=0.75,"On Track",IF(K36>=0.4,"At Risk","Off Track"))) -> Target Met
A37: NY-006 | B37: Sound Shore Manufacturing Plant | C37: Energy Use Intensity (EUI) | D37: kWh/sq ft | E37: Lower is better | F37: 13.7 | G37: 2019 | H37: ='Asset-Level Data'!O7 -> 10.214208 | I37: =F37*(1-$Q$4) -> 10.96 | J37: 2030 | K37: =(F37-H37)/(F37-I37) -> 1.2721868 | L37: =H37-I37 -> -0.74579184 | M37: =IF(K37>=1,"Target Met",IF(K37>=0.75,"On Track",IF(K37>=0.4,"At Risk","Off Track"))) -> Target Met
A38: NY-007 | B38: Saw Mill Flex Industrial Campus | C38: Energy Use Intensity (EUI) | D38: kWh/sq ft | E38: Lower is better | F38: 27.5 | G38: 2019 | H38: ='Asset-Level Data'!O8 -> 21.794486 | I38: =F38*(1-$Q$4) -> 22 | J38: 2030 | K38: =(F38-H38)/(F38-I38) -> 1.0373661 | L38: =H38-I38 -> -0.20551351 | M38: =IF(K38>=1,"Target Met",IF(K38>=0.75,"On Track",IF(K38>=0.4,"At Risk","Off Track"))) -> Target Met
A39: NY-008 | B39: Broadway Corridor Warehouse | C39: Energy Use Intensity (EUI) | D39: kWh/sq ft | E39: Lower is better | F39: 17.4 | G39: 2019 | H39: ='Asset-Level Data'!O9 -> 13.227885 | I39: =F39*(1-$Q$4) -> 13.92 | J39: 2030 | K39: =(F39-H39)/(F39-I39) -> 1.1988836 | L39: =H39-I39 -> -0.69211497 | M39: =IF(K39>=1,"Target Met",IF(K39>=0.75,"On Track",IF(K39>=0.4,"At Risk","Off Track"))) -> Target Met
A40: NY-009 | B40: Sunrise Supply Chain Center | C40: Energy Use Intensity (EUI) | D40: kWh/sq ft | E40: Lower is better | F40: 12.9 | G40: 2019 | H40: ='Asset-Level Data'!O10 -> 10.999315 | I40: =F40*(1-$Q$4) -> 10.32 | J40: 2030 | K40: =(F40-H40)/(F40-I40) -> 0.73669962 | L40: =H40-I40 -> 0.67931497 | M40: =IF(K40>=1,"Target Met",IF(K40>=0.75,"On Track",IF(K40>=0.4,"At Risk","Off Track"))) -> At Risk
A41: NY-010 | B41: Great South Bay Distribution Center | C41: Energy Use Intensity (EUI) | D41: kWh/sq ft | E41: Lower is better | F41: 11.6 | G41: 2019 | H41: ='Asset-Level Data'!O11 -> 9.9625502 | I41: =F41*(1-$Q$4) -> 9.28 | J41: 2030 | K41: =(F41-H41)/(F41-I41) -> 0.70579734 | L41: =H41-I41 -> 0.68255016 | M41: =IF(K41>=1,"Target Met",IF(K41>=0.75,"On Track",IF(K41>=0.4,"At Risk","Off Track"))) -> At Risk
A42: NY-011 | B42: Long Island Logistics Hub | C42: Energy Use Intensity (EUI) | D42: kWh/sq ft | E42: Lower is better | F42: 23 | G42: 2019 | H42: ='Asset-Level Data'!O12 -> 18.976982 | I42: =F42*(1-$Q$4) -> 18.4 | J42: 2030 | K42: =(F42-H42)/(F42-I42) -> 0.87456903 | L42: =H42-I42 -> 0.57698246 | M42: =IF(K42>=1,"Target Met",IF(K42>=0.75,"On Track",IF(K42>=0.4,"At Risk","Off Track"))) -> On Track
A43: NY-012 | B43: Bethpage Industrial Park - Bldg 1 | C43: Energy Use Intensity (EUI) | D43: kWh/sq ft | E43: Lower is better | F43: 13.8 | G43: 2019 | H43: ='Asset-Level Data'!O13 -> 10.204057 | I43: =F43*(1-$Q$4) -> 11.04 | J43: 2030 | K43: =(F43-H43)/(F43-I43) -> 1.3028779 | L43: =H43-I43 -> -0.83594291 | M43: =IF(K43>=1,"Target Met",IF(K43>=0.75,"On Track",IF(K43>=0.4,"At Risk","Off Track"))) -> Target Met
... A61: NY-030 | B61: State Street Capital Mixed-Use Tower | C61: Energy Use Intensity (EUI) | D61: kWh/sq ft | E61: Lower is better | F61: 25.3 | G61: 2019 | H61: ='Asset-Level Data'!O31 -> 19.357714 | I61: =F61*(1-$Q$4) -> 20.24 | J61: 2030 | K61: =(F61-H61)/(F61-I61) -> 1.1743648 | L61: =H61-I61 -> -0.88228571 | M61: =IF(K61>=1,"Target Met",IF(K61>=0.75,"On Track",IF(K61>=0.4,"At Risk","Off Track"))) -> Target Met
A62: NY-001 | B62: Hunts Point Logistics Hub | C62: Water Use (WT1) | D62: gal | E62: Lower is better | F62: 306816.4 | G62: 2019 | H62: ='Asset-Level Data'!T2 -> 1980000 | I62: =F62*(1-$Q$5) -> 260793.94 | J62: 2030 | K62: =(F62-H62)/(F62-I62) -> -36.355805 | L62: =H62-I62 -> 1719206.1 | M62: =IF(K62>=1,"Target Met",IF(K62>=0.75,"On Track",IF(K62>=0.4,"At Risk","Off Track"))) -> Off Track
A63: NY-002 | B63: Navy Yard Industrial Park - Bldg 1 | C63: Water Use (WT1) | D63: gal | E63: Lower is better | F63: 2312124.4 | G63: 2019 | H63: ='Asset-Level Data'!T3 -> 1950469 | I63: =F63*(1-$Q$5) -> 1965305.7 | J63: 2030 | K63: =(F63-H63)/(F63-I63) -> 1.0427795 | L63: =H63-I63 -> -14836.74 | M63: =IF(K63>=1,"Target Met",IF(K63>=0.75,"On Track",IF(K63>=0.4,"At Risk","Off Track"))) -> Target Met
A64: NY-003 | B64: LIC Fulfillment Center | C64: Water Use (WT1) | D64: gal | E64: Lower is better | F64: 2583311.9 | G64: 2019 | H64: ='Asset-Level Data'!T4 -> 2025433 | I64: =F64*(1-$Q$5) -> 2195815.1 | J64: 2030 | K64: =(F64-H64)/(F64-I64) -> 1.4396994 | L64: =H64-I64 -> -170382.11 | M64: =IF(K64>=1,"Target Met",IF(K64>=0.75,"On Track",IF(K64>=0.4,"At Risk","Off Track"))) -> Target Met
A65: NY-004 | B65: Harbor View Cross-Dock Terminal | C65: Water Use (WT1) | D65: gal | E65: Lower is better | F65: 3260679.1 | G65: 2019 | H65: ='Asset-Level Data'!T5 -> 3089988 | I65: =F65*(1-$Q$5) -> 2771577.2 | J65: 2030 | K65: =(F65-H65)/(F65-I65) -> 0.34898886 | L65: =H65-I65 -> 318410.77 | M65: =IF(K65>=1,"Target Met",IF(K65>=0.75,"On Track",IF(K65>=0.4,"At Risk","Off Track"))) -> Off Track
...

Sheet Compliance Exposure (LL97)
A1: Asset ID | B1: Asset Name | C1: Property Type | D1: Floor Area (sq ft) | E1: LL97 Applicable | F1: Current Annual Emissions - Scope 1+2 (mtCO2e) | G1: 2024-2029 Emissions Limit (mtCO2e) | H1: Over/(Under) Cap 2024-2029 (mtCO2e) | I1: Estimated Fine Exposure 2024-2029 ($) | J1: 2030-2034 Emissions Limit (mtCO2e) | K1: Projected Over/(Under) Cap 2030-2034 (mtCO2e) | L1: Projected Fine Exposure 2030-2034 ($) | M1: LL84 Filing Status | N1: LL84 Next Filing Deadline | O1: Days to Deadline | P1: Non-Filing Penalty Rate ($/month if unfiled) | Q1: Other NYC Local Laws Applicable | R1: Compliance Status 2024-2029 | S1: Compliance Status 2030-2034 (Projected) | U1: Property Type | V1: Limit 2024-2029 (mtCO2e/sq ft) | W1: Limit 2030-2034 (mtCO2e/sq ft)
A2: NY-001 | B2: Hunts Point Logistics Hub | C2: Manufacturing | D2: ='Asset-Level Data'!K2 -> 80000 | E2: =IF(D2>=25000,"Yes","No") -> Yes | F2: ='Asset-Level Data'!P2+'Asset-Level Data'!Q2 -> 527.13076 | G2: =D2*VLOOKUP(C2,$U$2:$W$8,2,FALSE()) -> 407.2 | H2: =F2-G2 -> 119.93076 | I2: =MAX(0,H2)*$V$11 -> 32141.444 | J2: =D2*VLOOKUP(C2,$U$2:$W$8,3,FALSE()) -> 252 | K2: =F2-J2 -> 275.13076 | L2: =MAX(0,K2)*$V$11 -> 73735.044 | M2: Filed | N2: =$V$13 -> 46508 | O2: =N2-TODAY() -> 265 | P2: =D2*$V$12 -> 40000 | Q2: LL84, LL88, LL33 | R2: =IF(H2<=0,"Compliant",IF(H2/G2<=0.1,"At Risk","Non-Compliant")) -> Non-Compliant | S2: =IF(K2<=0,"Compliant",IF(K2/J2<=0.1,"At Risk","Non-Compliant")) -> Non-Compliant | U2: Warehouse/Distribution | V2: 0.00206 | W2: 0.00128
A3: NY-002 | B3: Navy Yard Industrial Park - Bldg 1 | C3: Cold Storage | D3: ='Asset-Level Data'!K3 -> 339000 | E3: =IF(D3>=25000,"Yes","No") -> Yes | F3: ='Asset-Level Data'!P3+'Asset-Level Data'!Q3 -> 824.10586 | G3: =D3*VLOOKUP(C3,$U$2:$W$8,2,FALSE()) -> 993.27 | H3: =F3-G3 -> -169.16414 | I3: =MAX(0,H3)*$V$11 -> 0 | J3: =D3*VLOOKUP(C3,$U$2:$W$8,3,FALSE()) -> 616.98 | K3: =F3-J3 -> 207.12586 | L3: =MAX(0,K3)*$V$11 -> 55509.73 | M3: Not Filed | N3: =$V$13 -> 46508 | O3: =N3-TODAY() -> 265 | P3: =D3*$V$12 -> 169500 | Q3: LL84, LL88, LL33 | R3: =IF(H3<=0,"Compliant",IF(H3/G3<=0.1,"At Risk","Non-Compliant")) -> Compliant | S3: =IF(K3<=0,"Compliant",IF(K3/J3<=0.1,"At Risk","Non-Compliant")) -> Non-Compliant | U3: Manufacturing | V3: 0.00509 | W3: 0.00315
A4: NY-003 | B4: LIC Fulfillment Center | C4: Flex Industrial | D4: ='Asset-Level Data'!K4 -> 293000 | E4: =IF(D4>=25000,"Yes","No") -> Yes | F4: ='Asset-Level Data'!P4+'Asset-Level Data'!Q4 -> 987.60002 | G4: =D4*VLOOKUP(C4,$U$2:$W$8,2,FALSE()) -> 823.33 | H4: =F4-G4 -> 164.27002 | I4: =MAX(0,H4)*$V$11 -> 44024.365 | J4: =D4*VLOOKUP(C4,$U$2:$W$8,3,FALSE()) -> 509.82 | K4: =F4-J4 -> 477.78002 | L4: =MAX(0,K4)*$V$11 -> 128045.05 | M4: Filed - Late | N4: =$V$13 -> 46508 | O4: =N4-TODAY() -> 265 | P4: =D4*$V$12 -> 146500 | Q4: LL84, LL88, LL33 | R4: =IF(H4<=0,"Compliant",IF(H4/G4<=0.1,"At Risk","Non-Compliant")) -> Non-Compliant | S4: =IF(K4<=0,"Compliant",IF(K4/J4<=0.1,"At Risk","Non-Compliant")) -> Non-Compliant | U4: Cold Storage | V4: 0.00293 | W4: 0.00182
A5: NY-004 | B5: Harbor View Cross-Dock Terminal | C5: Light Industrial | D5: ='Asset-Level Data'!K5 -> 289000 | E5: =IF(D5>=25000,"Yes","No") -> Yes | F5: ='Asset-Level Data'!P5+'Asset-Level Data'!Q5 -> 721.12016 | G5: =D5*VLOOKUP(C5,$U$2:$W$8,2,FALSE()) -> 930.58 | H5: =F5-G5 -> -209.45984 | I5: =MAX(0,H5)*$V$11 -> 0 | J5: =D5*VLOOKUP(C5,$U$2:$W$8,3,FALSE()) -> 578 | K5: =F5-J5 -> 143.12016 | L5: =MAX(0,K5)*$V$11 -> 38356.203 | M5: Filed | N5: =$V$13 -> 46508 | O5: =N5-TODAY() -> 265 | P5: =D5*$V$12 -> 144500 | Q5: LL84, LL88, LL33 | R5: =IF(H5<=0,"Compliant",IF(H5/G5<=0.1,"At Risk","Non-Compliant")) -> Compliant | S5: =IF(K5<=0,"Compliant",IF(K5/J5<=0.1,"At Risk","Non-Compliant")) -> Non-Compliant | U5: Flex Industrial | V5: 0.00281 | W5: 0.00174
A6: NY-005 | B6: Cross-County Cold Storage Facility | C6: Logistics/Cross-dock | D6: ='Asset-Level Data'!K6 -> 279000 | E6: =IF(D6>=25000,"Yes","No") -> Yes | F6: ='Asset-Level Data'!P6+'Asset-Level Data'!Q6 -> 757.94096 | G6: =D6*VLOOKUP(C6,$U$2:$W$8,2,FALSE()) -> 1037.88 | H6: =F6-G6 -> -279.93904 | I6: =MAX(0,H6)*$V$11 -> 0 | J6: =D6*VLOOKUP(C6,$U$2:$W$8,3,FALSE()) -> 644.49 | K6: =F6-J6 -> 113.45096 | L6: =MAX(0,K6)*$V$11 -> 30404.857 | M6: Filed | N6: =$V$13 -> 46508 | O6: =N6-TODAY() -> 265 | P6: =D6*$V$12 -> 139500 | Q6: LL84, LL87 (audit due 2029), LL88, LL33 | R6: =IF(H6<=0,"Compliant",IF(H6/G6<=0.1,"At Risk","Non-Compliant")) -> Compliant | S6: =IF(K6<=0,"Compliant",IF(K6/J6<=0.1,"At Risk","Non-Compliant")) -> Non-Compliant | U6: Light Industrial | V6: 0.00322 | W6: 0.002
A7: NY-006 | B7: Sound Shore Manufacturing Plant | C7: Warehouse/Distribution | D7: ='Asset-Level Data'!K7 -> 711000 | E7: =IF(D7>=25000,"Yes","No") -> Yes | F7: ='Asset-Level Data'!P7+'Asset-Level Data'!Q7 -> 1352.9144 | G7: =D7*VLOOKUP(C7,$U$2:$W$8,2,FALSE()) -> 1464.66 | H7: =F7-G7 -> -111.74564 | I7: =MAX(0,H7)*$V$11 -> 0 | J7: =D7*VLOOKUP(C7,$U$2:$W$8,3,FALSE()) -> 910.08 | K7: =F7-J7 -> 442.83436 | L7: =MAX(0,K7)*$V$11 -> 118679.61 | M7: Filed | N7: =$V$13 -> 46508 | O7: =N7-TODAY() -> 265 | P7: =D7*$V$12 -> 355500 | Q7: LL84, LL87 (audit due 2029), LL88, LL33 | R7: =IF(H7<=0,"Compliant",IF(H7/G7<=0.1,"At Risk","Non-Compliant")) -> Compliant | S7: =IF(K7<=0,"Compliant",IF(K7/J7<=0.1,"At Risk","Non-Compliant")) -> Non-Compliant | U7: Logistics/Cross-dock | V7: 0.00372 | W7: 0.00231
A8: NY-007 | B8: Saw Mill Flex Industrial Campus | C8: Manufacturing | D8: ='Asset-Level Data'!K8 -> 74000 | E8: =IF(D8>=25000,"Yes","No") -> Yes | F8: ='Asset-Level Data'!P8+'Asset-Level Data'!Q8 -> 445.90256 | G8: =D8*VLOOKUP(C8,$U$2:$W$8,2,FALSE()) -> 376.66 | H8: =F8-G8 -> 69.24256 | I8: =MAX(0,H8)*$V$11 -> 18557.006 | J8: =D8*VLOOKUP(C8,$U$2:$W$8,3,FALSE()) -> 233.1 | K8: =F8-J8 -> 212.80256 | L8: =MAX(0,K8)*$V$11 -> 57031.086 | M8: Filed | N8: =$V$13 -> 46508 | O8: =N8-TODAY() -> 265 | P8: =D8*$V$12 -> 37000 | Q8: LL84, LL88, LL33 | R8: =IF(H8<=0,"Compliant",IF(H8/G8<=0.1,"At Risk","Non-Compliant")) -> Non-Compliant | S8: =IF(K8<=0,"Compliant",IF(K8/J8<=0.1,"At Risk","Non-Compliant")) -> Non-Compliant | U8: Mixed-Use Residential/Commercial | V8: 0.0041 | W8: 0.00254
A9: NY-008 | B9: Broadway Corridor Warehouse | C9: Cold Storage | D9: ='Asset-Level Data'!K9 -> 374000 | E9: =IF(D9>=25000,"Yes","No") -> Yes | F9: ='Asset-Level Data'!P9+'Asset-Level Data'!Q9 -> 905.40122 | G9: =D9*VLOOKUP(C9,$U$2:$W$8,2,FALSE()) -> 1095.82 | H9: =F9-G9 -> -190.41878 | I9: =MAX(0,H9)*$V$11 -> 0 | J9: =D9*VLOOKUP(C9,$U$2:$W$8,3,FALSE()) -> 680.68 | K9: =F9-J9 -> 224.72122 | L9: =MAX(0,K9)*$V$11 -> 60225.287 | M9: Filed | N9: =$V$13 -> 46508 | O9: =N9-TODAY() -> 265 | P9: =D9*$V$12 -> 187000 | Q9: LL84, LL87 (audit due 2027), LL88, LL33 | R9: =IF(H9<=0,"Compliant",IF(H9/G9<=0.1,"At Risk","Non-Compliant")) -> Compliant | S9: =IF(K9<=0,"Compliant",IF(K9/J9<=0.1,"At Risk","Non-Compliant")) -> Non-Compliant
A10: NY-009 | B10: Sunrise Supply Chain Center | C10: Flex Industrial | D10: ='Asset-Level Data'!K10 -> 581000 | E10: =IF(D10>=25000,"Yes","No") -> Yes | F10: ='Asset-Level Data'!P10+'Asset-Level Data'!Q10 -> 1197.4084 | G10: =D10*VLOOKUP(C10,$U$2:$W$8,2,FALSE()) -> 1632.61 | H10: =F10-G10 -> -435.20164 | I10: =MAX(0,H10)*$V$11 -> 0 | J10: =D10*VLOOKUP(C10,$U$2:$W$8,3,FALSE()) -> 1010.94 | K10: =F10-J10 -> 186.46836 | L10: =MAX(0,K10)*$V$11 -> 49973.52 | M10: Filed | N10: =$V$13 -> 46508 | O10: =N10-TODAY() -> 265 | P10: =D10*$V$12 -> 290500 | Q10: LL84, LL88, LL33 | R10: =IF(H10<=0,"Compliant",IF(H10/G10<=0.1,"At Risk","Non-Compliant")) -> Compliant | S10: =IF(K10<=0,"Compliant",IF(K10/J10<=0.1,"At Risk","Non-Compliant")) -> Non-Compliant | U10: Assumptions (fabricated demo data)
A11: NY-010 | B11: Great South Bay Distribution Center | C11: Light Industrial | D11: ='Asset-Level Data'!K11 -> 309000 | E11: =IF(D11>=25000,"Yes","No") -> Yes | F11: ='Asset-Level Data'!P11+'Asset-Level Data'!Q11 -> 1079.317 | G11: =D11*VLOOKUP(C11,$U$2:$W$8,2,FALSE()) -> 994.98 | H11: =F11-G11 -> 84.33704 | I11: =MAX(0,H11)*$V$11 -> 22602.327 | J11: =D11*VLOOKUP(C11,$U$2:$W$8,3,FALSE()) -> 618 | K11: =F11-J11 -> 461.31704 | L11: =MAX(0,K11)*$V$11 -> 123632.97 | M11: Filed | N11: =$V$13 -> 46508 | O11: =N11-TODAY() -> 265 | P11: =D11*$V$12 -> 154500 | Q11: LL84, LL87 (audit due 2027), LL88, LL33 | R11: =IF(H11<=0,"Compliant",IF(H11/G11<=0.1,"At Risk","Non-Compliant")) -> At Risk | S11: =IF(K11<=0,"Compliant",IF(K11/J11<=0.1,"At Risk","Non-Compliant")) -> Non-Compliant | U11: LL97 penalty rate ($/mtCO2e over cap) | V11: 268
A12: NY-011 | B12: Long Island Logistics Hub | C12: Logistics/Cross-dock | D12: ='Asset-Level Data'!K12 -> 57000 | E12: =IF(D12>=25000,"Yes","No") -> Yes | F12: ='Asset-Level Data'!P12+'Asset-Level Data'!Q12 -> 252.10384 | G12: =D12*VLOOKUP(C12,$U$2:$W$8,2,FALSE()) -> 212.04 | H12: =F12-G12 -> 40.06384 | I12: =MAX(0,H12)*$V$11 -> 10737.109 | J12: =D12*VLOOKUP(C12,$U$2:$W$8,3,FALSE()) -> 131.67 | K12: =F12-J12 -> 120.43384 | L12: =MAX(0,K12)*$V$11 -> 32276.269 | M12: Filed | N12: =$V$13 -> 46508 | O12: =N12-TODAY() -> 265 | P12: =D12*$V$12 -> 28500 | Q12: LL84, LL87 (audit due 2029), LL88, LL33 | R12: =IF(H12<=0,"Compliant",IF(H12/G12<=0.1,"At Risk","Non-Compliant")) -> Non-Compliant | S12: =IF(K12<=0,"Compliant",IF(K12/J12<=0.1,"At Risk","Non-Compliant")) -> Non-Compliant | U12: LL84 non-filing penalty rate ($/sq ft/month) | V12: 0.5
A13: NY-012 | B13: Bethpage Industrial Park - Bldg 1 | C13: Warehouse/Distribution | D13: ='Asset-Level Data'!K13 -> 543000 | E13: =IF(D13>=25000,"Yes","No") -> Yes | F13: ='Asset-Level Data'!P13+'Asset-Level Data'!Q13 -> 1118.1445 | G13: =D13*VLOOKUP(C13,$U$2:$W$8,2,FALSE()) -> 1118.58 | H13: =F13-G13 -> -0.43546 | I13: =MAX(0,H13)*$V$11 -> 0 | J13: =D13*VLOOKUP(C13,$U$2:$W$8,3,FALSE()) -> 695.04 | K13: =F13-J13 -> 423.10454 | L13: =MAX(0,K13)*$V$11 -> 113392.02 | M13: Filed | N13: =$V$13 -> 46508 | O13: =N13-TODAY() -> 265 | P13: =D13*$V$12 -> 271500 | Q13: LL84, LL87 (audit due 2029), LL88, LL33 | R13: =IF(H13<=0,"Compliant",IF(H13/G13<=0.1,"At Risk","Non-Compliant")) -> Compliant | S13: =IF(K13<=0,"Compliant",IF(K13/J13<=0.1,"At Risk","Non-Compliant")) -> Non-Compliant | U13: Next LL84 annual filing deadline | V13: 46508
A14: NY-013 | B14: Half Hollow Fulfillment Center | C14: Manufacturing | D14: ='Asset-Level Data'!K14 -> 299000 | E14: =IF(D14>=25000,"Yes","No") -> Yes | F14: ='Asset-Level Data'!P14+'Asset-Level Data'!Q14 -> 1520.8319 | G14: =D14*VLOOKUP(C14,$U$2:$W$8,2,FALSE()) -> 1521.91 | H14: =F14-G14 -> -1.07812 | I14: =MAX(0,H14)*$V$11 -> 0 | J14: =D14*VLOOKUP(C14,$U$2:$W$8,3,FALSE()) -> 941.85 | K14: =F14-J14 -> 578.98188 | L14: =MAX(0,K14)*$V$11 -> 155167.14 | M14: Filed | N14: =$V$13 -> 46508 | O14: =N14-TODAY() -> 265 | P14: =D14*$V$12 -> 149500 | Q14: LL84, LL88, LL33 | R14: =IF(H14<=0,"Compliant",IF(H14/G14<=0.1,"At Risk","Non-Compliant")) -> Compliant | S14: =IF(K14<=0,"Compliant",IF(K14/J14<=0.1,"At Risk","Non-Compliant")) -> Non-Compliant
A15: NY-014 | B15: Hudson Valley Cross-Dock Terminal | C15: Cold Storage | D15: ='Asset-Level Data'!K15 -> 346000 | E15: =IF(D15>=25000,"Yes","No") -> Yes | F15: ='Asset-Level Data'!P15+'Asset-Level Data'!Q15 -> 1150.8705 | G15: =D15*VLOOKUP(C15,$U$2:$W$8,2,FALSE()) -> 1013.78 | H15: =F15-G15 -> 137.09046 | I15: =MAX(0,H15)*$V$11 -> 36740.243 | J15: =D15*VLOOKUP(C15,$U$2:$W$8,3,FALSE()) -> 629.72 | K15: =F15-J15 -> 521.15046 | L15: =MAX(0,K15)*$V$11 -> 139668.32 | M15: Filed | N15: =$V$13 -> 46508 | O15: =N15-TODAY() -> 265 | P15: =D15*$V$12 -> 173000 | Q15: LL84, LL87 (audit due 2027), LL88, LL33 | R15: =IF(H15<=0,"Compliant",IF(H15/G15<=0.1,"At Risk","Non-Compliant")) -> Non-Compliant | S15: =IF(K15<=0,"Compliant",IF(K15/J15<=0.1,"At Risk","Non-Compliant")) -> Non-Compliant | U15: Emissions limits (columns V:W above) are illustrative, fabricated approximations for prototyping - NOT the real NYC DOB occupancy-group limits. The Mixed-Use Residential/Commercial limit is a single blended figure; real LL97 applies separate occupancy-group limits to the residential and commercial portions of a mixed-use building. Replace with the actual Local Law 97 covered-building limit tables before using for real compliance decisions.
A16: NY-015 | B16: Mid-Hudson Cold Storage Facility | C16: Flex Industrial | D16: ='Asset-Level Data'!K16 -> 263000 | E16: =IF(D16>=25000,"Yes","No") -> Yes | F16: ='Asset-Level Data'!P16+'Asset-Level Data'!Q16 -> 716.68488 | G16: =D16*VLOOKUP(C16,$U$2:$W$8,2,FALSE()) -> 739.03 | H16: =F16-G16 -> -22.34512 | I16: =MAX(0,H16)*$V$11 -> 0 | J16: =D16*VLOOKUP(C16,$U$2:$W$8,3,FALSE()) -> 457.62 | K16: =F16-J16 -> 259.06488 | L16: =MAX(0,K16)*$V$11 -> 69429.388 | M16: Filed | N16: =$V$13 -> 46508 | O16: =N16-TODAY() -> 265 | P16: =D16*$V$12 -> 131500 | Q16: LL84, LL88, LL33 | R16: =IF(H16<=0,"Compliant",IF(H16/G16<=0.1,"At Risk","Non-Compliant")) -> Compliant | S16: =IF(K16<=0,"Compliant",IF(K16/J16<=0.1,"At Risk","Non-Compliant")) -> Non-Compliant
A17: NY-016 | B17: Rondout Manufacturing Plant | C17: Light Industrial | D17: ='Asset-Level Data'!K17 -> 613000 | E17: =IF(D17>=25000,"Yes","No") -> Yes | F17: ='Asset-Level Data'!P17+'Asset-Level Data'!Q17 -> 1973.2386 | G17: =D17*VLOOKUP(C17,$U$2:$W$8,2,FALSE()) -> 1973.86 | H17: =F17-G17 -> -0.6214 | I17: =MAX(0,H17)*$V$11 -> 0 | J17: =D17*VLOOKUP(C17,$U$2:$W$8,3,FALSE()) -> 1226 | K17: =F17-J17 -> 747.2386 | L17: =MAX(0,K17)*$V$11 -> 200259.94 | M17: Filed | N17: =$V$13 -> 46508 | O17: =N17-TODAY() -> 265 | P17: =D17*$V$12 -> 306500 | Q17: LL84, LL88, LL33 | R17: =IF(H17<=0,"Compliant",IF(H17/G17<=0.1,"At Risk","Non-Compliant")) -> Compliant | S17: =IF(K17<=0,"Compliant",IF(K17/J17<=0.1,"At Risk","Non-Compliant")) -> Non-Compliant
A18: NY-017 | B18: Capital Region Flex Industrial Campus | C18: Logistics/Cross-dock | D18: ='Asset-Level Data'!K18 -> 477000 | E18: =IF(D18>=25000,"Yes","No") -> Yes | F18: ='Asset-Level Data'!P18+'Asset-Level Data'!Q18 -> 1137.9801 | G18: =D18*VLOOKUP(C18,$U$2:$W$8,2,FALSE()) -> 1774.44 | H18: =F18-G18 -> -636.45988 | I18: =MAX(0,H18)*$V$11 -> 0 | J18: =D18*VLOOKUP(C18,$U$2:$W$8,3,FALSE()) -> 1101.87 | K18: =F18-J18 -> 36.11012 | L18: =MAX(0,K18)*$V$11 -> 9677.5122 | M18: Filed - Late | N18: =$V$13 -> 46508 | O18: =N18-TODAY() -> 265 | P18: =D18*$V$12 -> 238500 | Q18: LL84, LL87 (audit due 2027), LL88, LL33 | R18: =IF(H18<=0,"Compliant",IF(H18/G18<=0.1,"At Risk","Non-Compliant")) -> Compliant | S18: =IF(K18<=0,"Compliant",IF(K18/J18<=0.1,"At Risk","Non-Compliant")) -> At Risk
A19: NY-018 | B19: Mohawk Valley Warehouse | C19: Warehouse/Distribution | D19: ='Asset-Level Data'!K19 -> 79000 | E19: =IF(D19>=25000,"Yes","No") -> Yes | F19: ='Asset-Level Data'!P19+'Asset-Level Data'!Q19 -> 210.02412 | G19: =D19*VLOOKUP(C19,$U$2:$W$8,2,FALSE()) -> 162.74 | H19: =F19-G19 -> 47.28412 | I19: =MAX(0,H19)*$V$11 -> 12672.144 | J19: =D19*VLOOKUP(C19,$U$2:$W$8,3,FALSE()) -> 101.12 | K19: =F19-J19 -> 108.90412 | L19: =MAX(0,K19)*$V$11 -> 29186.304 | M19: Filed | N19: =$V$13 -> 46508 | O19: =N19-TODAY() -> 265 | P19: =D19*$V$12 -> 39500 | Q19: LL84, LL88, LL33 | R19: =IF(H19<=0,"Compliant",IF(H19/G19<=0.1,"At Risk","Non-Compliant")) -> Non-Compliant | S19: =IF(K19<=0,"Compliant",IF(K19/J19<=0.1,"At Risk","Non-Compliant")) -> Non-Compliant
A20: NY-019 | B20: Hudson-Mohawk Supply Chain Center | C20: Manufacturing | D20: ='Asset-Level Data'!K20 -> 449000 | E20: =IF(D20>=25000,"Yes","No") -> Yes | F20: ='Asset-Level Data'!P20+'Asset-Level Data'!Q20 -> 1034.6823 | G20: =D20*VLOOKUP(C20,$U$2:$W$8,2,FALSE()) -> 2285.41 | H20: =F20-G20 -> -1250.7277 | I20: =MAX(0,H20)*$V$11 -> 0 | J20: =D20*VLOOKUP(C20,$U$2:$W$8,3,FALSE()) -> 1414.35 | K20: =F20-J20 -> -379.66766 | L20: =MAX(0,K20)*$V$11 -> 0 | M20: Filed | N20: =$V$13 -> 46508 | O20: =N20-TODAY() -> 265 | P20: =D20*$V$12 -> 224500 | Q20: LL84, LL87 (audit due 2027), LL88, LL33 | R20: =IF(H20<=0,"Compliant",IF(H20/G20<=0.1,"At Risk","Non-Compliant")) -> Compliant | S20: =IF(K20<=0,"Compliant",IF(K20/J20<=0.1,"At Risk","Non-Compliant")) -> Compliant
A21: NY-020 | B21: Central New York Distribution Center | C21: Cold Storage | D21: ='Asset-Level Data'!K21 -> 574000 | E21: =IF(D21>=25000,"Yes","No") -> Yes | F21: ='Asset-Level Data'!P21+'Asset-Level Data'!Q21 -> 1681.924 | G21: =D21*VLOOKUP(C21,$U$2:$W$8,2,FALSE()) -> 1681.82 | H21: =F21-G21 -> 0.10402 | I21: =MAX(0,H21)*$V$11 -> 27.87736 | J21: =D21*VLOOKUP(C21,$U$2:$W$8,3,FALSE()) -> 1044.68 | K21: =F21-J21 -> 637.24402 | L21: =MAX(0,K21)*$V$11 -> 170781.4 | M21: Filed | N21: =$V$13 -> 46508 | O21: =N21-TODAY() -> 265 | P21: =D21*$V$12 -> 287000 | Q21: LL84, LL88, LL33 | R21: =IF(H21<=0,"Compliant",IF(H21/G21<=0.1,"At Risk","Non-Compliant")) -> At Risk | S21: =IF(K21<=0,"Compliant",IF(K21/J21<=0.1,"At Risk","Non-Compliant")) -> Non-Compliant
A22: NY-021 | B22: Genesee Valley Logistics Hub | C22: Flex Industrial | D22: ='Asset-Level Data'!K22 -> 531000 | E22: =IF(D22>=25000,"Yes","No") -> Yes | F22: ='Asset-Level Data'!P22+'Asset-Level Data'!Q22 -> 1492.8521 | G22: =D22*VLOOKUP(C22,$U$2:$W$8,2,FALSE()) -> 1492.11 | H22: =F22-G22 -> 0.74206 | I22: =MAX(0,H22)*$V$11 -> 198.87208 | J22: =D22*VLOOKUP(C22,$U$2:$W$8,3,FALSE()) -> 923.94 | K22: =F22-J22 -> 568.91206 | L22: =MAX(0,K22)*$V$11 -> 152468.43 | M22: Filed | N22: =$V$13 -> 46508 | O22: =N22-TODAY() -> 265 | P22: =D22*$V$12 -> 265500 | Q22: LL84, LL88, LL33 | R22: =IF(H22<=0,"Compliant",IF(H22/G22<=0.1,"At Risk","Non-Compliant")) -> At Risk | S22: =IF(K22<=0,"Compliant",IF(K22/J22<=0.1,"At Risk","Non-Compliant")) -> Non-Compliant
A23: NY-022 | B23: Queen City Industrial Park - Bldg 1 | C23: Light Industrial | D23: ='Asset-Level Data'!K23 -> 680000 | E23: =IF(D23>=25000,"Yes","No") -> Yes | F23: ='Asset-Level Data'!P23+'Asset-Level Data'!Q23 -> 2141.986 | G23: =D23*VLOOKUP(C23,$U$2:$W$8,2,FALSE()) -> 2189.6 | H23: =F23-G23 -> -47.61396 | I23: =MAX(0,H23)*$V$11 -> 0 | J23: =D23*VLOOKUP(C23,$U$2:$W$8,3,FALSE()) -> 1360 | K23: =F23-J23 -> 781.98604 | L23: =MAX(0,K23)*$V$11 -> 209572.26 | M23: Filed - Late | N23: =$V$13 -> 46508 | O23: =N23-TODAY() -> 265 | P23: =D23*$V$12 -> 340000 | Q23: LL84, LL88, LL33 | R23: =IF(H23<=0,"Compliant",IF(H23/G23<=0.1,"At Risk","Non-Compliant")) -> Compliant | S23: =IF(K23<=0,"Compliant",IF(K23/J23<=0.1,"At Risk","Non-Compliant")) -> Non-Compliant
A24: NY-023 | B24: Cheektowaga Gateway Fulfillment Center | C24: Logistics/Cross-dock | D24: ='Asset-Level Data'!K24 -> 522000 | E24: =IF(D24>=25000,"Yes","No") -> Yes | F24: ='Asset-Level Data'!P24+'Asset-Level Data'!Q24 -> 1941.252 | G24: =D24*VLOOKUP(C24,$U$2:$W$8,2,FALSE()) -> 1941.84 | H24: =F24-G24 -> -0.58802 | I24: =MAX(0,H24)*$V$11 -> 0 | J24: =D24*VLOOKUP(C24,$U$2:$W$8,3,FALSE()) -> 1205.82 | K24: =F24-J24 -> 735.43198 | L24: =MAX(0,K24)*$V$11 -> 197095.77 | M24: Not Filed | N24: =$V$13 -> 46508 | O24: =N24-TODAY() -> 265 | P24: =D24*$V$12 -> 261000 | Q24: LL84, LL87 (audit due 2029), LL88, LL33 | R24: =IF(H24<=0,"Compliant",IF(H24/G24<=0.1,"At Risk","Non-Compliant")) -> Compliant | S24: =IF(K24<=0,"Compliant",IF(K24/J24<=0.1,"At Risk","Non-Compliant")) -> Non-Compliant
A25: NY-024 | B25: Mohawk Corridor Cross-Dock Terminal | C25: Warehouse/Distribution | D25: ='Asset-Level Data'!K25 -> 551000 | E25: =IF(D25>=25000,"Yes","No") -> Yes | F25: ='Asset-Level Data'!P25+'Asset-Level Data'!Q25 -> 1108.8271 | G25: =D25*VLOOKUP(C25,$U$2:$W$8,2,FALSE()) -> 1135.06 | H25: =F25-G25 -> -26.23292 | I25: =MAX(0,H25)*$V$11 -> 0 | J25: =D25*VLOOKUP(C25,$U$2:$W$8,3,FALSE()) -> 705.28 | K25: =F25-J25 -> 403.54708 | L25: =MAX(0,K25)*$V$11 -> 108150.62 | M25: Filed | N25: =$V$13 -> 46508 | O25: =N25-TODAY() -> 265 | P25: =D25*$V$12 -> 275500 | Q25: LL84, LL88, LL33 | R25: =IF(H25<=0,"Compliant",IF(H25/G25<=0.1,"At Risk","Non-Compliant")) -> Compliant | S25: =IF(K25<=0,"Compliant",IF(K25/J25<=0.1,"At Risk","Non-Compliant")) -> Non-Compliant
A26: NY-025 | B26: Empire Corridor Cold Storage Facility | C26: Manufacturing | D26: ='Asset-Level Data'!K26 -> 653000 | E26: =IF(D26>=25000,"Yes","No") -> Yes | F26: ='Asset-Level Data'!P26+'Asset-Level Data'!Q26 -> 2699.4933 | G26: =D26*VLOOKUP(C26,$U$2:$W$8,2,FALSE()) -> 3323.77 | H26: =F26-G26 -> -624.27666 | I26: =MAX(0,H26)*$V$11 -> 0 | J26: =D26*VLOOKUP(C26,$U$2:$W$8,3,FALSE()) -> 2056.95 | K26: =F26-J26 -> 642.54334 | L26: =MAX(0,K26)*$V$11 -> 172201.62 | M26: Filed | N26: =$V$13 -> 46508 | O26: =N26-TODAY() -> 265 | P26: =D26*$V$12 -> 326500 | Q26: LL84, LL88, LL33 | R26: =IF(H26<=0,"Compliant",IF(H26/G26<=0.1,"At Risk","Non-Compliant")) -> Compliant | S26: =IF(K26<=0,"Compliant",IF(K26/J26<=0.1,"At Risk","Non-Compliant")) -> Non-Compliant
A27: NY-026 | B27: Fulton Street Mixed-Use Tower | C27: Mixed-Use Residential/Commercial | D27: ='Asset-Level Data'!K27 -> 447000 | E27: =IF(D27>=25000,"Yes","No") -> Yes | F27: ='Asset-Level Data'!P27+'Asset-Level Data'!Q27 -> 1766.4745 | G27: =D27*VLOOKUP(C27,$U$2:$W$8,2,FALSE()) -> 1832.7 | H27: =F27-G27 -> -66.22548 | I27: =MAX(0,H27)*$V$11 -> 0 | J27: =D27*VLOOKUP(C27,$U$2:$W$8,3,FALSE()) -> 1135.38 | K27: =F27-J27 -> 631.09452 | L27: =MAX(0,K27)*$V$11 -> 169133.33 | M27: Filed | N27: =$V$13 -> 46508 | O27: =N27-TODAY() -> 265 | P27: =D27*$V$12 -> 223500 | Q27: LL84, LL88, LL33 | R27: =IF(H27<=0,"Compliant",IF(H27/G27<=0.1,"At Risk","Non-Compliant")) -> Compliant | S27: =IF(K27<=0,"Compliant",IF(K27/J27<=0.1,"At Risk","Non-Compliant")) -> Non-Compliant
... A31: NY-030 | B31: State Street Capital Mixed-Use Tower | C31: Mixed-Use Residential/Commercial | D31: ='Asset-Level Data'!K31 -> 252000 | E31: =IF(D31>=25000,"Yes","No") -> Yes | F31: ='Asset-Level Data'!P31+'Asset-Level Data'!Q31 -> 1033.8659 | G31: =D31*VLOOKUP(C31,$U$2:$W$8,2,FALSE()) -> 1033.2 | H31: =F31-G31 -> 0.66592 | I31: =MAX(0,H31)*$V$11 -> 178.46656 | J31: =D31*VLOOKUP(C31,$U$2:$W$8,3,FALSE()) -> 640.08 | K31: =F31-J31 -> 393.78592 | L31: =MAX(0,K31)*$V$11 -> 105534.63 | M31: Filed | N31: =$V$13 -> 46508 | O31: =N31-TODAY() -> 265 | P31: =D31*$V$12 -> 126000 | Q31: LL84, LL87 (audit due 2029), LL88, LL33 | R31: =IF(H31<=0,"Compliant",IF(H31/G31<=0.1,"At Risk","Non-Compliant")) -> At Risk | S31: =IF(K31<=0,"Compliant",IF(K31/J31<=0.1,"At Risk","Non-Compliant")) -> Non-Compliant
B33: PORTFOLIO TOTAL | I33: =SUM(I2:I31) -> 340682.61 | L33: =SUM(L2:L31) -> 3405112 | R33: =COUNTIF(R2:R31,"Non-Compliant")&" non-compliant, "&COUNTIF(R2:R31,"At Risk")&" at risk, "&COUNTIF(R2:R31,"Compliant")&" compliant" -> 8 non-compliant, 4 at risk, 18 compliant

Sheet Management (Entity-Level)
A1: Indicator Code | B1: Aspect | C1: Indicator Name | D1: Response / Status | E1: Portfolio Coverage (%) | F1: Evidence / Document Reference | G1: Owner / Accountable Role | H1: Last Reviewed | I1: Points Earned | J1: Max Points | K1: Notes
A2: LE1 | B2: Leadership | C2: Senior decision-maker accountable for sustainability | D2: Yes - Chief Sustainability Officer | F2: Org chart v3, Board Charter Sec. 4.2 | G2: Chief Sustainability Officer | H2: 2026-02-10 | I2: 2 | J2: 2 | K2: Reports directly to CEO
A3: LE2 | B3: Leadership | C3: Board-level oversight of ESG strategy | D3: Yes - quarterly board review | F3: Board minutes, Q1-Q4 2025 | G3: Board of Directors | H3: 2026-01-15 | I3: 2 | J3: 2 | K3: Standing agenda item
A4: LE3 | B4: Leadership | C4: ESG performance linked to variable compensation | D4: Partial - applies to CSO and asset mgmt leads only | E4: 1 | F4: Compensation policy v2.1 | G4: Head of HR | H4: 2025-11-01 | I4: 1 | J4: 2 | K4: Not yet extended to property-level staff
A5: LE4 | B5: Leadership | C5: Dedicated sustainability team or function | D5: Yes - 3 FTE sustainability team | F5: Org chart v3 | G5: Chief Sustainability Officer | H5: 2026-02-10 | I5: 2 | J5: 2 | K5: Team formed 2023
A6: PO1 | B6: Policies | C6: Documented environmental policy | D6: Yes | E6: 1 | F6: Environmental Policy v4, effective 2025-06-01 | G6: Chief Sustainability Officer | H6: 2025-06-01 | I6: 2 | J6: 2 | K6: Covers energy, emissions, water, waste
A7: PO2 | B7: Policies | C7: Documented social policy | D7: Yes | E7: 1 | F7: Social Responsibility Policy v2 | G7: Head of HR | H7: 2025-03-14 | I7: 2 | J7: 2 | K7: Covers labor practices, tenant relations
A8: PO3 | B8: Policies | C8: Documented governance / anti-corruption policy | D8: Yes | E8: 1 | F8: Code of Business Conduct v5 | G8: General Counsel | H8: 2025-09-20 | I8: 2 | J8: 2 | K8: Annual employee attestation required
A9: RE1 | B9: Reporting | C9: Reports against a recognized external framework | D9: Yes - GRI and TCFD-aligned | F9: 2025 Annual ESG Report, published 2026-03-01 | G9: Chief Sustainability Officer | H9: 2026-03-01 | I9: 2 | J9: 2 | K9: First TCFD-aligned disclosure in 2024
A10: RE2 | B10: Reporting | C10: Third-party assurance of reported ESG data | D10: Partial - limited assurance on Scope 1+2 only | F10: Assurance Statement, ABC Assurance LLP | G10: Chief Financial Officer | H10: 2026-03-01 | I10: 1 | J10: 2 | K10: Reasonable assurance targeted for 2027 cycle
A11: RE3 | B11: Reporting | C11: Public ESG disclosure (CDP or equivalent) | D11: Yes - CDP Climate submission | F11: CDP Climate Change Response 2025 | G11: Chief Sustainability Officer | H11: 2025-07-31 | I11: 2 | J11: 2 | K11: Score: B (2025 cycle)
A12: RM1 | B12: Risk Management | C12: Environmental Management System (EMS) in place | D12: Yes - ISO 14001-aligned, not certified | E12: 0.82 | F12: EMS Manual v3 | G12: Director of Facilities | H12: 2025-08-12 | I12: 2 | J12: 2 | K12: Certification planned FY2027
A13: RM2 | B13: Risk Management | C13: Process to implement governance policies | D13: Yes - documented rollout & training process | F13: Governance Rollout SOP | G13: General Counsel | H13: 2025-09-20 | I13: 2 | J13: 2 | K13: Annual refresher training
A14: RM3.1 | B14: Risk Management | C14: Social risk assessment process | D14: Yes - annual assessment | F14: Social Risk Register 2025 | G14: Head of HR | H14: 2025-12-01 | I14: 1 | J14: 2 | K14: Covers labor and tenant-relations risk
A15: RM3.2 | B15: Risk Management | C15: Governance risk assessment process | D15: Yes - annual assessment | F15: Governance Risk Register 2025 | G15: General Counsel | H15: 2025-12-01 | I15: 2 | J15: 2
A16: RM4.1 | B16: Risk Management | C16: Sustainability due diligence for new acquisitions | D16: Yes - standard acquisition checklist | F16: Acquisition ESG Checklist v2 | G16: Head of Acquisitions | H16: 2025-10-05 | I16: 2 | J16: 2 | K16: Applied to 3 acquisitions in 2025
A17: RM4.2 | B17: Risk Management | C17: Embodied carbon assessed in acquisitions | D17: No - not yet incorporated | G17: Head of Acquisitions | I17: 0 | J17: 2 | K17: Identified as 2027 roadmap item
A18: RM5 | B18: Risk Management | C18: Climate resilience strategy | D18: Partial - flood risk only, no heat/wind resilience plan | E18: 1 | F18: Climate Resilience Memo 2025 | G18: Chief Sustainability Officer | H18: 2025-11-15 | I18: 1 | J18: 2 | K18: Flood modeling complete for all NY assets
A19: RM6.1 | B19: Risk Management | C19: Transition risk identification process | D19: Yes - annual screening incl. LL97/BPS exposure | E19: 1 | F19: Transition Risk Screening 2025 | G19: Chief Sustainability Officer | H19: 2025-12-10 | I19: 2 | J19: 2 | K19: Uses CRREM pathways
A20: RM6.2 | B20: Risk Management | C20: Transition risk impact assessment (financial) | D20: Yes - $ exposure modeled per asset | E20: 1 | F20: LL97 Exposure Model v3 | G20: Chief Financial Officer | H20: 2025-12-10 | I20: 2 | J20: 2 | K20: Feeds portfolio compliance-exposure metric
A21: RM6.3 | B21: Risk Management | C21: Physical risk identification process | D21: Yes - flood, extreme heat screened | E21: 1 | F21: Physical Risk Screening 2025 | G21: Director of Facilities | H21: 2025-11-15 | I21: 2 | J21: 2
A22: RM6.4 | B22: Risk Management | C22: Physical risk impact assessment (financial) | D22: Partial - flood only, heat impact not yet quantified | E22: 0.4 | F22: Physical Risk Screening 2025 | G22: Director of Facilities | H22: 2025-11-15 | I22: 1 | J22: 2
A23: RM7 | B23: Risk Management | C23: Biodiversity / nature-related strategy | D23: No - not yet developed | G23: Chief Sustainability Officer | I23: 0 | J23: 1 | K23: Low materiality for industrial portfolio; under review
A24: SE1 | B24: Stakeholder Engagement | C24: Tenant engagement program | D24: Yes - annual tenant sustainability survey | E24: 0.76 | F24: Tenant Survey Results 2025 | G24: Director of Property Management | H24: 2025-10-20 | I24: 2 | J24: 2 | K24: 76% of tenants by floor area responded
A25: SE2 | B25: Stakeholder Engagement | C25: Employee engagement on sustainability | D25: Yes - annual training + internal newsletter | F25: Training completion log 2025 | G25: Head of HR | H25: 2025-09-01 | I25: 1 | J25: 2 | K25: 92% completion rate
A26: SE3 | B26: Stakeholder Engagement | C26: Community engagement program | D26: Partial - ad hoc only, no formal program | F26: Community outreach log 2025 | G26: Chief Sustainability Officer | H26: 2025-06-30 | I26: 1 | J26: 2 | K26: Formal program planned FY2027
A27: SE4 | B27: Stakeholder Engagement | C27: Investor / LP ESG engagement | D27: Yes - quarterly ESG briefing to LPs | F27: LP Quarterly ESG Briefing deck, Q4 2025 | G27: Head of Investor Relations | H27: 2026-01-20 | I27: 2 | J27: 2 | K27: Includes GRESB score walkthrough
C29: TOTAL - MANAGEMENT COMPONENT | I29: =SUM(I2:I27) -> 41 | J29: =SUM(J2:J27) -> 51
C30: % of Management Component achieved | I30: =I29/J29 -> 0.80392157

Sheet Legend & Notes
A1: Field | B1: Definition
A2: EN1 | B2: GRESB energy indicator - total energy imported/purchased, generated on-site, and exported/sold, per building.
A3: EUI | B3: Energy Use Intensity = EN1 Imported / Floor Area (kWh/sq ft). Portfolio EUI should be floor-area-weighted, not simple-averaged.
A4: GH1 | B4: GRESB GHG indicator - Scope 1 (on-site combustion), Scope 2 location-based (mandatory) and market-based (optional), Scope 3 (unscored).
A5: WT1 / WT2 | B5: GRESB water indicators - total withdrawals/inflows (WT1) and discharge to sensitive waterways (WT2).
A6: WS1 | B6: GRESB waste indicator - diversion/recycling rate.
A7: BC1.1 / BC1.2 / BC2 | B7: GRESB building certification indicators - design/construction, operational, and ongoing certification status.
A8: Data Coverage | B8: % of floor area / consumption with verified data for that asset. Portfolio rollup should be floor-area-weighted.
A9: Confidence Tier | B9: Verified = utility API/submeter feed. Estimated = derived or interpolated. Missing = no reliable data source.
A11: Aggregation method
A12: Sum | B12: Floor area, EN1, GH1, WT1/WT2 - additive totals across the portfolio.
A13: Floor-area-weighted average | B13: EUI, Waste Diversion Rate, Data Coverage, ENERGY STAR Score - must be weighted, not simple-averaged, so larger buildings are represented proportionally.
A15: Data notes
A16: Coverage | B16: All data in this workbook is fabricated for prototyping and does not represent real buildings, addresses, or performance.
A17: Grid factor | B17: GH1 Scope 2 (location-based) uses an illustrative NY grid emission factor of 0.00018 mtCO2e/kWh (see 'Assumptions' block, cells AF1:AG4, on the Asset-Level Data sheet). Not sourced from eGRID; replace with the correct NYUP/NYCW subregion factor before using for real reporting.
A19: Management (Entity-Level) tab
A20: Structure | B20: Management indicators are answered once per reporting entity, not per building - this tab has one row per indicator, not one row per asset. Fabricated for prototyping.
A21: Aspects | B21: Leadership, Policies, Reporting, Risk Management, Stakeholder Engagement - mirrors the 2026 GRESB Real Estate Management Component structure.
A23: Baseline & Targets tab
A24: Structure | B24: Long format: one row per asset per Performance metric (6 metrics x 25 assets = 150 rows). Current Value is formula-linked to the Asset-Level Data tab; Baseline Value is fabricated; Target Value is either a formula-derived reduction from baseline (GHG, EUI, Water) or a fixed portfolio-wide goal (Waste Diversion, ENERGY STAR, Data Coverage) - see the Assumptions block, columns P:Q, on the Baseline & Targets sheet.
A25: Status thresholds | B25: Target Met (>=100% progress), On Track (>=75%), At Risk (>=40%), Off Track (<40%). Progress can exceed 100% (asset has surpassed its target) or go negative (asset has moved further from baseline).
A27: Data fix - 2026-08-07
